Workbook

Sheet אינדקס
I1: =CONCATENATE("🎯 מטרות-העל: ", 'אינדקס'!$B$5) -> 🎯 מטרות-העל: https://docs.google.com/open?id=16lBROr6DmzGS3AaRedcxxBk5nYQMegngfhrp90Jz1JQ
A2: 🏠 את/ה באינדקס | C2: מעבר מהיר לגיליון: | D2: משימות | E2: אנשי קשר
A4: אינדקס גיליונות - ישויות לאיפיון
A5: מטרות-העל של הפרויקט: | B5: https://docs.google.com/open?id=16lBROr6DmzGS3AaRedcxxBk5nYQMegngfhrp90Jz1JQ
A6: שם הגיליון (ישות) החדש:
A7: לחצו על כפתור 'הוסף גיליון' (לאחר הזנת שם) - הכפתור נוסף לאחר פתיחה ב-Google Sheets
A9: שם הגיליון (ישות) למחיקה:
A10: לחצו על כפתור 'מחק גיליון' - הפעולה בלתי הפיכה, תתבקשו לאשר
A12: # | B12: שם הגיליון (ישות) | C12: קישור
B13: לקוחות | C13: לקוחות
A14: 1 | B14: בק אנד (מערכת) | C14: בק אנד (סוגי יישויות)
A15: 2 | B15: אנשי קשר | C15: אנשי קשר
A16: 3 | B16: קטלוג שירותים | C16: =HYPERLINK("https://docs.google.com/spreadsheets/d/1ON4l0rpY35dBfrB0jgjQFR2HGOe-jhxxfXIZdIrogkA/edit#gid=1217484634", "פתח גיליון") -> פתח גיליון
A17: 5 | B17: עסקאות | C17: =HYPERLINK("https://docs.google.com/spreadsheets/d/1ON4l0rpY35dBfrB0jgjQFR2HGOe-jhxxfXIZdIrogkA/edit#gid=656135550", "פתח גיליון") -> פתח גיליון
A18: 6 | B18: תקשורת | C18: =HYPERLINK("https://docs.google.com/spreadsheets/d/1ON4l0rpY35dBfrB0jgjQFR2HGOe-jhxxfXIZdIrogkA/edit#gid=1722217642", "פתח גיליון") -> פתח גיליון
A19: 7 | B19: משימות | C19: =HYPERLINK("https://docs.google.com/spreadsheets/d/1ON4l0rpY35dBfrB0jgjQFR2HGOe-jhxxfXIZdIrogkA/edit#gid=927433692", "פתח גיליון") -> פתח גיליון
A20: 8 | B20: עובד משרד | C20: =HYPERLINK("https://docs.google.com/spreadsheets/d/1ON4l0rpY35dBfrB0jgjQFR2HGOe-jhxxfXIZdIrogkA/edit#gid=1125570332", "פתח גיליון") -> פתח גיליון
A21: 9 | B21: תבניות חובת דיווח | C21: =HYPERLINK("https://docs.google.com/spreadsheets/d/1ON4l0rpY35dBfrB0jgjQFR2HGOe-jhxxfXIZdIrogkA/edit#gid=2004086106", "פתח גיליון") -> פתח גיליון
A22: 10 | B22: הגשות | C22: =HYPERLINK("https://docs.google.com/spreadsheets/d/1ON4l0rpY35dBfrB0jgjQFR2HGOe-jhxxfXIZdIrogkA/edit#gid=645958431", "פתח גיליון") -> פתח גיליון
A23: 11 | B23: דרישת חומר תקופתי | C23: =HYPERLINK("https://docs.google.com/spreadsheets/d/1ON4l0rpY35dBfrB0jgjQFR2HGOe-jhxxfXIZdIrogkA/edit#gid=779002980", "פתח גיליון") -> פתח גיליון
A24: 12 | B24: מסמכים | C24: =HYPERLINK("https://docs.google.com/spreadsheets/d/1ON4l0rpY35dBfrB0jgjQFR2HGOe-jhxxfXIZdIrogkA/edit#gid=2048049799", "פתח גיליון") -> פתח גיליון
A25: 13 | B25: אישורים והוראות לקוח | C25: =HYPERLINK("https://docs.google.com/spreadsheets/d/1ON4l0rpY35dBfrB0jgjQFR2HGOe-jhxxfXIZdIrogkA/edit#gid=641230538", "פתח גיליון") -> פתח גיליון
A26: 14 | B26: חובות מס לתשלום | C26: =HYPERLINK("https://docs.google.com/spreadsheets/d/1ON4l0rpY35dBfrB0jgjQFR2HGOe-jhxxfXIZdIrogkA/edit#gid=23401743", "פתח גיליון") -> פתח גיליון
A27: 14 | B27: תבנית חובת תשלום | C27: =HYPERLINK("https://docs.google.com/spreadsheets/d/1ON4l0rpY35dBfrB0jgjQFR2HGOe-jhxxfXIZdIrogkA/edit#gid=1441623654", "פתח גיליון") -> פתח גיליון
A28: 15 | B28: הרצת שכר | C28: =HYPERLINK("https://docs.google.com/spreadsheets/d/1ON4l0rpY35dBfrB0jgjQFR2HGOe-jhxxfXIZdIrogkA/edit#gid=1206338352", "פתח גיליון") -> פתח גיליון
A29: 16 | B29: רשימת עובדי לקוחות | C29: =HYPERLINK("https://docs.google.com/spreadsheets/d/1ON4l0rpY35dBfrB0jgjQFR2HGOe-jhxxfXIZdIrogkA/edit#gid=1592369228", "פתח גיליון") -> פתח גיליון

Sheet תבנית
G1: מעבר לדף הבית | H1: מעבר מהיר לגיליון: | I1: ZDSFA | J1: =VLOOKUP(I1,'אינדקס'!B13:C91,2) -> פתח גיליון | L1: מעבר לתהליכי עבודה | S1: מעבר לטבלת השדות | U1: מעבר לדף הבית | V1: מעבר מהיר לגיליון: | W1: DFA | X1: =VLOOKUP(W1,'אינדקס'!B13:C91,2) -> פתח גיליון
F2: =CONCATENATE("🎯 מטרות-העל: ", 'אינדקס'!$B$5) -> 🎯 מטרות-העל: https://docs.google.com/open?id=16lBROr6DmzGS3AaRedcxxBk5nYQMegngfhrp90Jz1JQ | T2: =CONCATENATE("🎯 מטרות-העל: ", 'אינדקס'!$B$5) -> 🎯 מטרות-העל: https://docs.google.com/open?id=16lBROr6DmzGS3AaRedcxxBk5nYQMegngfhrp90Jz1JQ
F4: =IF(G4="","",ROW()-6) | R4: =IF(S4="","",ROW()-6) | T4: =IF(U4="","",ROW()-6)
F5: =IF(G5="","",ROW()-6) | R5: =IF(S5="","",ROW()-6) | T5: =IF(U5="","",ROW()-6)
F6: =IF(G6="","",ROW()-6) | R6: =IF(S6="","",ROW()-6) | T6: =IF(U6="","",ROW()-6)
F7: =IF(G7="","",ROW()-6) | R7: =IF(S7="","",ROW()-6) | T7: =IF(U7="","",ROW()-6)
F9: # | G9: קבוצת שדות | H9: שם שדה | I9: סוג שדה | J9: חובה/רשות | K9: ערכים אפשריים | L9: הערות | R9: # | S9: שם התהליך | T9: סוג טריגר | U9: פרטי טריגר | V9: תנאי הפעלה (שדה+לוגיקה) | W9: סטטוס איפיון | X9: הערות | AA9: שם תהליך | AB9: סוג פעולה | AC9: תיואר פעולה קצר | AD9: תיאור מפורט
B10: שם קבוצה | C10: חוזת או לא | F10: =IF(G10="","",ROW()-9) | J10: FALSE | R10: =IF(S10="","",ROW()-6)
C11: FALSE | F11: =IF(G11="","",ROW()-9) | J11: FALSE | R11: =IF(S11="","",ROW()-6)
C12: FALSE | F12: =IF(G12="","",ROW()-9) | J12: FALSE | R12: =IF(S12="","",ROW()-6)
C13: FALSE | F13: =IF(G13="","",ROW()-9) | J13: FALSE | R13: =IF(S13="","",ROW()-6)
C14: FALSE | F14: =IF(G14="","",ROW()-9) | J14: FALSE | R14: =IF(S14="","",ROW()-6)
C15: FALSE | F15: =IF(G15="","",ROW()-9) | J15: FALSE | R15: =IF(S15="","",ROW()-6)
C16: FALSE | F16: =IF(G16="","",ROW()-9) | J16: FALSE | R16: =IF(S16="","",ROW()-6)
C17: FALSE | F17: =IF(G17="","",ROW()-9) | J17: FALSE | R17: =IF(S17="","",ROW()-6)
C18: FALSE | F18: =IF(G18="","",ROW()-9) | J18: FALSE | R18: =IF(S18="","",ROW()-6)
C19: FALSE | F19: =IF(G19="","",ROW()-9) | J19: FALSE | R19: =IF(S19="","",ROW()-6)
C20: FALSE | F20: =IF(G20="","",ROW()-9) | J20: FALSE | R20: =IF(S20="","",ROW()-6)
C21: FALSE | F21: =IF(G21="","",ROW()-9) | J21: FALSE | R21: =IF(S21="","",ROW()-6)
C22: FALSE | F22: =IF(G22="","",ROW()-9) | J22: FALSE | R22: =IF(S22="","",ROW()-6)
... C30: FALSE | F30: =IF(G30="","",ROW()-9) | J30: FALSE | R30: =IF(S30="","",ROW()-6)
F31: =IF(G31="","",ROW()-9) | J31: FALSE | R31: =IF(S31="","",ROW()-6)
F32: =IF(G32="","",ROW()-9) | J32: FALSE | R32: =IF(S32="","",ROW()-6)
F33: =IF(G33="","",ROW()-9) | J33: FALSE | R33: =IF(S33="","",ROW()-6)
F34: =IF(G34="","",ROW()-9) | J34: FALSE | R34: =IF(S34="","",ROW()-6)
F35: =IF(G35="","",ROW()-9) | J35: FALSE | R35: =IF(S35="","",ROW()-6)
F36: =IF(G36="","",ROW()-9) | J36: FALSE | R36: =IF(S36="","",ROW()-6)
F37: =IF(G37="","",ROW()-9) | J37: FALSE | R37: =IF(S37="","",ROW()-6)
F38: =IF(G38="","",ROW()-9) | J38: FALSE | R38: =IF(S38="","",ROW()-6)
F39: =IF(G39="","",ROW()-9) | J39: FALSE | R39: =IF(S39="","",ROW()-6)
F40: =IF(G40="","",ROW()-9) | J40: FALSE | R40: =IF(S40="","",ROW()-6)
F41: =IF(G41="","",ROW()-9) | J41: FALSE | R41: =IF(S41="","",ROW()-6)
F42: =IF(G42="","",ROW()-9) | J42: FALSE | R42: =IF(S42="","",ROW()-6)
... F69: =IF(G69="","",ROW()-9) | J69: FALSE | R69: =IF(S69="","",ROW()-6)
F70: =IF(G70="","",ROW()-6) | J70: FALSE | R70: =IF(S70="","",ROW()-6)
F71: =IF(G71="","",ROW()-6) | J71: FALSE | R71: =IF(S71="","",ROW()-6)
F72: =IF(G72="","",ROW()-6) | J72: FALSE | R72: =IF(S72="","",ROW()-6)
F73: =IF(G73="","",ROW()-6) | J73: FALSE | R73: =IF(S73="","",ROW()-6)
F74: =IF(G74="","",ROW()-6) | J74: FALSE | R74: =IF(S74="","",ROW()-6)
F75: =IF(G75="","",ROW()-6) | J75: FALSE | R75: =IF(S75="","",ROW()-6)
...

Sheet אנשי קשר
G1: מעבר לדף הבית | H1: מעבר מהיר לגיליון: | I1: ישעי קליין | J1: אנשי קשר | L1: מעבר לתהליכי עבודה | W1: מעבר לטבלת השדות | Y1: מעבר לדף הבית | Z1: מעבר מהיר לגיליון: | AA1: DFA | AB1: =VLOOKUP(AA1,'אינדקס'!B13:C91,2) -> פתח גיליון
F2: =CONCATENATE("🎯 מטרות-העל: ", 'אינדקס'!$B$5) -> 🎯 מטרות-העל: https://docs.google.com/open?id=16lBROr6DmzGS3AaRedcxxBk5nYQMegngfhrp90Jz1JQ | X2: =CONCATENATE("🎯 מטרות-העל: ", 'אינדקס'!$B$5) -> 🎯 מטרות-העל: https://docs.google.com/open?id=16lBROr6DmzGS3AaRedcxxBk5nYQMegngfhrp90Jz1JQ
F4: =IF(G4="","",ROW()-6) | V4: =IF(W4="","",ROW()-6) | X4: =IF(Y4="","",ROW()-6)
F5: =IF(G5="","",ROW()-6) | V5: =IF(W5="","",ROW()-6) | X5: =IF(Y5="","",ROW()-6)
F6: =IF(G6="","",ROW()-6) | V6: =IF(W6="","",ROW()-6) | X6: =IF(Y6="","",ROW()-6)
F7: =IF(G7="","",ROW()-6) | V7: =IF(W7="","",ROW()-6) | X7: =IF(Y7="","",ROW()-6)
F9: # | G9: קבוצת שדות | H9: שם שדה | I9: סוג שדה | J9: חובה/רשות | K9: ערכים אפשריים | L9: הערות | M9: הרשאות צפייה | N9: הרשאות עריכה | O9: הרשאות צפייה 2 | P9: הרשאות עריכה 2 | V9: # | W9: שם התהליך | X9: סוג טריגר | Y9: פרטי טריגר | Z9: תנאי הפעלה (שדה+לוגיקה) | AA9: סטטוס איפיון | AB9: הערות | AE9: שם תהליך | AF9: סוג פעולה | AG9: תיואר פעולה קצר | AH9: תיאור מפורט
B10: שם קבוצה | C10: חוזת או לא | F10: =IF(G10="","",ROW()-9) -> 1 | G10: פרטי איש קשר | H10: קישור ללקוח | I10: קישור למופע אחר | J10: TRUE | K10: יישות לקישור | V10: =IF(W10="","",ROW()-6)
B11: פרטי איש קשר | C11: FALSE | F11: =IF(G11="","",ROW()-9) -> 2 | G11: פרטי איש קשר | H11: שם פרטי | I11: שדה טקסט | J11: TRUE | V11: =IF(W11="","",ROW()-6)
B12: פרטי תקשורת | C12: TRUE | F12: =IF(G12="","",ROW()-9) -> 3 | G12: פרטי איש קשר | H12: שם משפחה | I12: שדה טקסט | J12: TRUE | V12: =IF(W12="","",ROW()-6)
C13: FALSE | F13: =IF(G13="","",ROW()-9) -> 4 | G13: פרטי איש קשר | H13: תפקיד | I13: תיבת בחירה | J13: TRUE | V13: =IF(W13="","",ROW()-6)
C14: FALSE | F14: =IF(G14="","",ROW()-9) -> 5 | G14: פרטי איש קשר | H14: הרשאות | I14: בחירה מרובה | J14: TRUE | V14: =IF(W14="","",ROW()-6)
C15: FALSE | F15: =IF(G15="","",ROW()-9) -> 6 | G15: פרטי איש קשר | H15: מידע נוסף | I15: איזור שדה טקסט | J15: FALSE | V15: =IF(W15="","",ROW()-6)
C16: FALSE | F16: =IF(G16="","",ROW()-9) -> 7 | G16: פרטי איש קשר | H16: תפקיד בהקלדה חופשית | I16: בחירה מרובה חופשית | J16: FALSE | V16: =IF(W16="","",ROW()-6)
C17: FALSE | F17: =IF(G17="","",ROW()-9) -> 8 | G17: פרטי איש קשר | H17: פירוט הרשאות | I17: איזור שדה טקסט | J17: FALSE | V17: =IF(W17="","",ROW()-6)
C18: FALSE | F18: =IF(G18="","",ROW()-9) -> 9 | G18: פרטי איש קשר | H18: תחומי אחריות | I18: בחירה מרובה | J18: FALSE | V18: =IF(W18="","",ROW()-6)
C19: FALSE | F19: =IF(G19="","",ROW()-9) -> 10 | G19: פרטי תקשורת | H19: סוג | I19: תיבת בחירה | J19: TRUE | K19: וואצאפ/פקס/אימייל/טלפון | V19: =IF(W19="","",ROW()-6)
C20: FALSE | F20: =IF(G20="","",ROW()-9) -> 11 | G20: פרטי תקשורת | H20: דוא"ל | I20: שדה דואר אלקטרוני | J20: TRUE | V20: =IF(W20="","",ROW()-6)
C21: FALSE | F21: =IF(G21="","",ROW()-9) -> 12 | G21: פרטי תקשורת | H21: טלפון | I21: שדה טלפון | J21: FALSE | V21: =IF(W21="","",ROW()-6)
C22: FALSE | F22: =IF(G22="","",ROW()-9) -> 13 | G22: פרטי תקשורת | H22: מידע נוסף | I22: שדה טקסט | J22: FALSE | V22: =IF(W22="","",ROW()-6)
C23: FALSE | F23: =IF(G23="","",ROW()-9) -> 14 | G23: פרטי תקשורת | H23: עדיפות תקשורת | I23: צ'ק בוקס | J23: FALSE | V23: =IF(W23="","",ROW()-6)
C24: FALSE | F24: =IF(G24="","",ROW()-9) | J24: FALSE | V24: =IF(W24="","",ROW()-6)
C25: FALSE | F25: =IF(G25="","",ROW()-9) | J25: FALSE | V25: =IF(W25="","",ROW()-6)
C26: FALSE | F26: =IF(G26="","",ROW()-9) | J26: FALSE | V26: =IF(W26="","",ROW()-6)
C27: FALSE | F27: =IF(G27="","",ROW()-9) | J27: FALSE | V27: =IF(W27="","",ROW()-6)
C28: FALSE | F28: =IF(G28="","",ROW()-9) | J28: FALSE | V28: =IF(W28="","",ROW()-6)
C29: FALSE | F29: =IF(G29="","",ROW()-9) | J29: FALSE | V29: =IF(W29="","",ROW()-6)
C30: FALSE | F30: =IF(G30="","",ROW()-9) | J30: FALSE | V30: =IF(W30="","",ROW()-6)
F31: =IF(G31="","",ROW()-9) | J31: FALSE | V31: =IF(W31="","",ROW()-6)
F32: =IF(G32="","",ROW()-9) | J32: FALSE | V32: =IF(W32="","",ROW()-6)
F33: =IF(G33="","",ROW()-9) | J33: FALSE | V33: =IF(W33="","",ROW()-6)
F34: =IF(G34="","",ROW()-9) | J34: FALSE | V34: =IF(W34="","",ROW()-6)
F35: =IF(G35="","",ROW()-9) | J35: FALSE | V35: =IF(W35="","",ROW()-6)
F36: =IF(G36="","",ROW()-9) | J36: FALSE | V36: =IF(W36="","",ROW()-6)
F37: =IF(G37="","",ROW()-9) | J37: FALSE | V37: =IF(W37="","",ROW()-6)
F38: =IF(G38="","",ROW()-9) | J38: FALSE | V38: =IF(W38="","",ROW()-6)
F39: =IF(G39="","",ROW()-9) | J39: FALSE | V39: =IF(W39="","",ROW()-6)
F40: =IF(G40="","",ROW()-9) | J40: FALSE | V40: =IF(W40="","",ROW()-6)
F41: =IF(G41="","",ROW()-9) | J41: FALSE | V41: =IF(W41="","",ROW()-6)
F42: =IF(G42="","",ROW()-9) | J42: FALSE | V42: =IF(W42="","",ROW()-6)
...

Sheet בק אנד (סוגי ישיות)
G1: מעבר לדף הבית | H1: מעבר מהיר לגיליון: | I1: ZDSFA | J1: =VLOOKUP(I1,'אינדקס'!B13:C91,2) -> פתח גיליון | L1: מעבר לתהליכי עבודה | W1: מעבר לטבלת השדות | Y1: מעבר לדף הבית | Z1: מעבר מהיר לגיליון: | AA1: DFA | AB1: =VLOOKUP(AA1,'אינדקס'!B13:C91,2) -> פתח גיליון
F2: =CONCATENATE("🎯 מטרות-העל: ", 'אינדקס'!$B$5) -> 🎯 מטרות-העל: https://docs.google.com/open?id=16lBROr6DmzGS3AaRedcxxBk5nYQMegngfhrp90Jz1JQ | X2: =CONCATENATE("🎯 מטרות-העל: ", 'אינדקס'!$B$5) -> 🎯 מטרות-העל: https://docs.google.com/open?id=16lBROr6DmzGS3AaRedcxxBk5nYQMegngfhrp90Jz1JQ
F4: =IF(G4="","",ROW()-6) | V4: =IF(W4="","",ROW()-6) | X4: =IF(Y4="","",ROW()-6)
F5: =IF(G5="","",ROW()-6) | V5: =IF(W5="","",ROW()-6) | X5: =IF(Y5="","",ROW()-6)
F6: =IF(G6="","",ROW()-6) | V6: =IF(W6="","",ROW()-6) | X6: =IF(Y6="","",ROW()-6)
F7: =IF(G7="","",ROW()-6) | V7: =IF(W7="","",ROW()-6) | X7: =IF(Y7="","",ROW()-6)
F9: # | G9: קבוצת שדות | H9: שם שדה | I9: סוג שדה | J9: חובה/רשות | K9: ערכים אפשריים | L9: הערות | M9: הרשאות צפייה | N9: הרשאות עריכה | O9: הרשאות צפייה 2 | P9: הרשאות עריכה 2 | V9: # | W9: שם התהליך | X9: סוג טריגר | Y9: פרטי טריגר | Z9: תנאי הפעלה (שדה+לוגיקה) | AA9: סטטוס איפיון | AB9: הערות | AE9: שם תהליך | AF9: סוג פעולה | AG9: תיואר פעולה קצר | AH9: תיאור מפורט
B10: שם קבוצה | C10: חוזת או לא | F10: =IF(G10="","",ROW()-9) -> 1 | G10: סוג יישיות | H10: שם הסוג | I10: שדה טקסט | J10: TRUE | V10: =IF(W10="","",ROW()-6)
B11: סוג יישיות | C11: FALSE | F11: =IF(G11="","",ROW()-9) -> 2 | G11: סוג יישיות | H11: שירותים רלוונטיים | I11: קישור למופעים מרובים | J11: FALSE | V11: =IF(W11="","",ROW()-6)
C12: FALSE | F12: =IF(G12="","",ROW()-9) | J12: FALSE | V12: =IF(W12="","",ROW()-6)
C13: FALSE | F13: =IF(G13="","",ROW()-9) | J13: FALSE | V13: =IF(W13="","",ROW()-6)
C14: FALSE | F14: =IF(G14="","",ROW()-9) | J14: FALSE | V14: =IF(W14="","",ROW()-6)
C15: FALSE | F15: =IF(G15="","",ROW()-9) | J15: FALSE | V15: =IF(W15="","",ROW()-6)
C16: FALSE | F16: =IF(G16="","",ROW()-9) | J16: FALSE | V16: =IF(W16="","",ROW()-6)
C17: FALSE | F17: =IF(G17="","",ROW()-9) | J17: FALSE | V17: =IF(W17="","",ROW()-6)
C18: FALSE | F18: =IF(G18="","",ROW()-9) | J18: FALSE | V18: =IF(W18="","",ROW()-6)
C19: FALSE | F19: =IF(G19="","",ROW()-9) | J19: FALSE | V19: =IF(W19="","",ROW()-6)
C20: FALSE | F20: =IF(G20="","",ROW()-9) | J20: FALSE | V20: =IF(W20="","",ROW()-6)
C21: FALSE | F21: =IF(G21="","",ROW()-9) | J21: FALSE | V21: =IF(W21="","",ROW()-6)
C22: FALSE | F22: =IF(G22="","",ROW()-9) | J22: FALSE | V22: =IF(W22="","",ROW()-6)
C23: FALSE | F23: =IF(G23="","",ROW()-9) | J23: FALSE | V23: =IF(W23="","",ROW()-6)
... C30: FALSE | F30: =IF(G30="","",ROW()-9) | J30: FALSE | V30: =IF(W30="","",ROW()-6)
F31: =IF(G31="","",ROW()-9) | J31: FALSE | V31: =IF(W31="","",ROW()-6)
F32: =IF(G32="","",ROW()-9) | J32: FALSE | V32: =IF(W32="","",ROW()-6)
F33: =IF(G33="","",ROW()-9) | J33: FALSE | V33: =IF(W33="","",ROW()-6)
F34: =IF(G34="","",ROW()-9) | J34: FALSE | V34: =IF(W34="","",ROW()-6)
F35: =IF(G35="","",ROW()-9) | J35: FALSE | V35: =IF(W35="","",ROW()-6)
F36: =IF(G36="","",ROW()-9) | J36: FALSE | V36: =IF(W36="","",ROW()-6)
F37: =IF(G37="","",ROW()-9) | J37: FALSE | V37: =IF(W37="","",ROW()-6)
F38: =IF(G38="","",ROW()-9) | J38: FALSE | V38: =IF(W38="","",ROW()-6)
F39: =IF(G39="","",ROW()-9) | J39: FALSE | V39: =IF(W39="","",ROW()-6)
F40: =IF(G40="","",ROW()-9) | J40: FALSE | V40: =IF(W40="","",ROW()-6)
F41: =IF(G41="","",ROW()-9) | J41: FALSE | V41: =IF(W41="","",ROW()-6)
F42: =IF(G42="","",ROW()-9) | J42: FALSE | V42: =IF(W42="","",ROW()-6)
... F69: =IF(G69="","",ROW()-9) | J69: FALSE | V69: =IF(W69="","",ROW()-6)
F70: =IF(G70="","",ROW()-6) | J70: FALSE | V70: =IF(W70="","",ROW()-6)
F71: =IF(G71="","",ROW()-6) | J71: FALSE | V71: =IF(W71="","",ROW()-6)
F72: =IF(G72="","",ROW()-6) | J72: FALSE | V72: =IF(W72="","",ROW()-6)
F73: =IF(G73="","",ROW()-6) | J73: FALSE | V73: =IF(W73="","",ROW()-6)
F74: =IF(G74="","",ROW()-6) | J74: FALSE | V74: =IF(W74="","",ROW()-6)
...

Sheet לקוחות
G1: מעבר לדף הבית | H1: מעבר מהיר לגיליון: | I1: משימות | J1: =VLOOKUP(I1,'אינדקס'!B13:C91,2,0) -> פתח גיליון | L1: מעבר לתהליכי עבודה | W1: מעבר לטבלת השדות | Y1: מעבר לדף הבית | Z1: מעבר מהיר לגיליון: | AA1: DFA | AB1: =VLOOKUP(AA1,'אינדקס'!B13:C91,2) -> פתח גיליון
F2: =CONCATENATE("🎯 מטרות-העל: ", 'אינדקס'!$B$5) -> 🎯 מטרות-העל: https://docs.google.com/open?id=16lBROr6DmzGS3AaRedcxxBk5nYQMegngfhrp90Jz1JQ | X2: =CONCATENATE("🎯 מטרות-העל: ", 'אינדקס'!$B$5) -> 🎯 מטרות-העל: https://docs.google.com/open?id=16lBROr6DmzGS3AaRedcxxBk5nYQMegngfhrp90Jz1JQ
E3: מטרת היישות יישות לקוח מאגדת את כל המידע שהמשרד שומר על לקוח ממידע שימושי ועד מידע כללי כל מידע שהוא קשור לעבודה סביב לקוח קיים פה כל מידע שחשוב לשמור על העסק החל ממידע גולמי ועד למשתנה ממססימאות ועד מידע יבש
F4: =IF(G4="","",ROW()-6) | V4: =IF(W4="","",ROW()-6) | X4: =IF(Y4="","",ROW()-6)
F5: =IF(G5="","",ROW()-6) | V5: =IF(W5="","",ROW()-6) | X5: =IF(Y5="","",ROW()-6)
F6: =IF(G6="","",ROW()-6) | V6: =IF(W6="","",ROW()-6) | X6: =IF(Y6="","",ROW()-6)
F7: =IF(G7="","",ROW()-6) | V7: =IF(W7="","",ROW()-6) | X7: =IF(Y7="","",ROW()-6)
F9: # | G9: טי | H9: שם שדה | I9: סוג שדה | J9: חובה/רשות | K9: ערכים אפשריים | L9: הערות | M9: הרשאות צפייה | N9: הרשאות עריכה | V9: # | W9: שם התהליך | X9: סוג טריגר | Y9: פרטי טריגר | Z9: תנאי הפעלה (שדה+לוגיקה) | AA9: סטטוס איפיון | AB9: הערות | AE9: שם תהליך | AF9: סוג פעולה | AG9: תיואר פעולה קצר | AH9: תיאור מפורט
B10: שם קבוצה | C10: חוזת או לא | F10: =IF(G10="","",ROW()-9) -> 1 | G10: הערה מקצועית | H10: תוכן ההערה | I10: איזור שדה טקסט | J10: FALSE | M10: מפתח / מנהל מערכת, בעל/ת המשרד, מנהל צוות, מנהל/ת חשבונות, חשב/ת שכר, יועץ/ת מס, מתמחה, מנהל/ת משרד, "צופה / רו""ח חיצוני", מערכת / אוטומציה | N10: מפתח / מנהל מערכת, בעל/ת המשרד, מנהל צוות, מנהל/ת חשבונות, חשב/ת שכר, יועץ/ת מס, מנהל/ת משרד, מערכת / אוטומציה | V10: =IF(W10="","",ROW()-6) -> 4 | W10: שם לקוח כאיש קשר | X10: מופע או שדה | Y10: בעת יצירת המופע | AA10: באפיון | AE10: שם לקוח כאיש קשר | AF10: המרת מופע | AG10: יצירת מופע ביישות "איש קשר עם פרטיו של הלוקח וסימון כבעלים
A11: פרטים איישים של לקוח מאגד תחתיו את המידע האישי על הלקוח עצמו זה שהוא חתום על העסקאות ונושא את האחריות האישית לכל ההסכמים | B11: פרטים אישיים לקוח | F11: =IF(G11="","",ROW()-9) -> 2 | G11: הערה מקצועית | H11: מס' | I11: בחירה מטווח מספרים | J11: FALSE | K11: מספר בלבד | L11: מיספור חשיבות | M11: מפתח / מנהל מערכת, בעל/ת המשרד, מנהל צוות, מנהל/ת חשבונות, חשב/ת שכר, יועץ/ת מס, מתמחה, מנהל/ת משרד, "צופה / רו""ח חיצוני", מערכת / אוטומציה | N11: מפתח / מנהל מערכת, בעל/ת המשרד, מנהל צוות, מנהל/ת חשבונות, חשב/ת שכר, יועץ/ת מס, מנהל/ת משרד, מערכת / אוטומציה | V11: =IF(W11="","",ROW()-6)
A12: פרטים החוקיים של היישות (העסק כהגדרתו החוקית) | B12: פרטי יישות משפטית | C12: FALSE | F12: =IF(G12="","",ROW()-6) -> 6 | G12: הערה מקצועית | H12: בתוקף? | I12: שדה נוסחה | J12: FALSE | K12: מחשב תוקף טקסטואלי | L12: חישוב עם עדיין בתוקף | M12: מפתח / מנהל מערכת, בעל/ת המשרד, מנהל צוות, מנהל/ת חשבונות, חשב/ת שכר, יועץ/ת מס, מתמחה, מנהל/ת משרד, "צופה / רו""ח חיצוני", מערכת / אוטומציה | N12: מפתח / מנהל מערכת, בעל/ת המשרד, מנהל צוות, מנהל/ת חשבונות, חשב/ת שכר, יועץ/ת מס, מנהל/ת משרד, מערכת / אוטומציה | V12: =IF(W12="","",ROW()-6)
A13: פריטיו המלאים על של העסק ועל העסק | B13: פרטי העסק | C13: FALSE | F13: =IF(G13="","",ROW()-6) -> 7 | G13: הערה מקצועית | H13: תאריך החלה | I13: שדה תאריך/זמן | J13: FALSE | M13: מפתח / מנהל מערכת, בעל/ת המשרד, מנהל צוות, מנהל/ת חשבונות, חשב/ת שכר, יועץ/ת מס, מתמחה, מנהל/ת משרד, "צופה / רו""ח חיצוני", מערכת / אוטומציה | N13: מפתח / מנהל מערכת, בעל/ת המשרד, מנהל צוות, מנהל/ת חשבונות, חשב/ת שכר, יועץ/ת מס, מנהל/ת משרד, מערכת / אוטומציה | V13: =IF(W13="","",ROW()-6)
A14: פרטי התקשורת הכללים של העסק הרשמיים ולא של איש קשר ספציפי | B14: פרטי תיקשורת כלליים | C14: TRUE | F14: =IF(G14="","",ROW()-6) -> 8 | G14: הערה מקצועית | H14: תאריך פקיעת תוקף | I14: שדה תאריך/זמן | J14: FALSE | M14: מפתח / מנהל מערכת, בעל/ת המשרד, מנהל צוות, מנהל/ת חשבונות, חשב/ת שכר, יועץ/ת מס, מתמחה, מנהל/ת משרד, "צופה / רו""ח חיצוני", מערכת / אוטומציה | N14: מפתח / מנהל מערכת, בעל/ת המשרד, מנהל צוות, מנהל/ת חשבונות, חשב/ת שכר, יועץ/ת מס, מנהל/ת משרד, מערכת / אוטומציה | V14: =IF(W14="","",ROW()-6)
A15: פרטין של הלקוח מול רשיות החוק והמדינה | B15: פרטים מול הרשויות | C15: FALSE | F15: =IF(G15="","",ROW()-6) -> 9 | G15: הערה מקצועית | H15: בתוקף ? מוסתר | I15: שדה נוסחה | J15: FALSE | K15: מחשב תוקף בינארי 0/1 | V15: =IF(W15="","",ROW()-6)
A16: פרטי חשבונות הבנק של העסק קבוצה חוזרת כדיעלתת אפשרות להוסיף חשבונות בלי הגבלה | B16: פרטי חשבון בנק | C16: TRUE | F16: =IF(G16="","",ROW()-9) -> 7 | G16: מידע חשוב | H16: שם מערכת | I16: שדה טקסט | J16: FALSE | M16: מפתח / מנהל מערכת, בעל/ת המשרד, מנהל צוות, מנהל/ת משרד | N16: מפתח / מנהל מערכת, בעל/ת המשרד, מנהל צוות, מנהל/ת משרד | V16: =IF(W16="","",ROW()-6)
A17: פרטי העסק כלקוח מתגייות ועד איש קשר רשמי וכו' | B17: פרטי לקוח | C17: FALSE | F17: =IF(G17="","",ROW()-6) -> 11 | G17: מידע חשוב | H17: שם משתמש | I17: שדה טקסט | J17: FALSE | M17: מפתח / מנהל מערכת, בעל/ת המשרד, מנהל צוות, מנהל/ת משרד | N17: מפתח / מנהל מערכת, בעל/ת המשרד, מנהל צוות, מנהל/ת משרד | V17: =IF(W17="","",ROW()-6)
A18: קבוצה חוזרת של הערות עם תוקף שיהי מידע רלוונטי לזמנים לדוגמא המנכ"ל בחופשא בין תאריכים X יש ליהות בקשר עם Y | B18: הערה מקצועית | C18: TRUE | F18: =IF(G18="","",ROW()-6) -> 12 | G18: מידע חשוב | H18: סיסמה | I18: שדה סיסמא | J18: FALSE | M18: מפתח / מנהל מערכת, בעל/ת המשרד, מנהל צוות, מנהל/ת משרד | N18: מפתח / מנהל מערכת, בעל/ת המשרד, מנהל צוות, מנהל/ת משרד | V18: =IF(W18="","",ROW()-6)
A19: מכיל את הקישוריות למעבר מהיר בין תכנים של הלקוח ביישות אחרות | B19: קישורים | C19: FALSE | F19: =IF(G19="","",ROW()-6) -> 13 | G19: מידע חשוב | H19: סוג היזדהות | I19: תיבת בחירה | J19: FALSE | M19: מפתח / מנהל מערכת, בעל/ת המשרד, מנהל צוות, מנהל/ת משרד | N19: מפתח / מנהל מערכת, בעל/ת המשרד, מנהל צוות, מנהל/ת משרד | V19: =IF(W19="","",ROW()-6)
A20: סיסמאות וכ' | B20: מידע חשוב | C20: TRUE | F20: =IF(G20="","",ROW()-6) -> 14 | G20: מידע חשוב | H20: תוקף | I20: שדה תאריך/זמן | J20: FALSE | M20: מפתח / מנהל מערכת, בעל/ת המשרד, מנהל צוות, מנהל/ת משרד | N20: מפתח / מנהל מערכת, בעל/ת המשרד, מנהל צוות, מנהל/ת משרד | V20: =IF(W20="","",ROW()-6)
C21: FALSE | F21: =IF(G21="","",ROW()-6) -> 15 | G21: מידע חשוב | H21: הערות | I21: איזור שדה טקסט | J21: FALSE | M21: מפתח / מנהל מערכת, בעל/ת המשרד, מנהל צוות, מנהל/ת משרד | N21: מפתח / מנהל מערכת, בעל/ת המשרד, מנהל צוות, מנהל/ת משרד | V21: =IF(W21="","",ROW()-6)
C22: FALSE | F22: =IF(G22="","",ROW()-6) -> 16 | G22: מידע חשוב | H22: תיוג | I22: בחירה מרובה חופשית | J22: FALSE | M22: מפתח / מנהל מערכת, בעל/ת המשרד, מנהל צוות, מנהל/ת משרד | N22: מפתח / מנהל מערכת, בעל/ת המשרד, מנהל צוות, מנהל/ת משרד | V22: =IF(W22="","",ROW()-6)
C23: FALSE | F23: =IF(G23="","",ROW()-9) -> 14 | G23: פרטי העסק | H23: שם העסק (מותג) | I23: שדה טקסט | J23: FALSE | M23: מפתח / מנהל מערכת, בעל/ת המשרד, מנהל צוות, מנהל/ת חשבונות, חשב/ת שכר, יועץ/ת מס, מתמחה, מנהל/ת משרד, "צופה / רו""ח חיצוני", לקוח (פורטל) | N23: מפתח / מנהל מערכת, בעל/ת המשרד, מנהל צוות, מנהל/ת משרד | V23: =IF(W23="","",ROW()-6)
C24: FALSE | F24: =IF(G24="","",ROW()-9) -> 15 | G24: פרטי העסק | H24: כתובת העסק | I24: בחירת כתובת | J24: FALSE | M24: מפתח / מנהל מערכת, בעל/ת המשרד, מנהל צוות, מנהל/ת חשבונות, חשב/ת שכר, יועץ/ת מס, מתמחה, מנהל/ת משרד, "צופה / רו""ח חיצוני", לקוח (פורטל) | N24: מפתח / מנהל מערכת, בעל/ת המשרד, מנהל צוות, מנהל/ת משרד | V24: =IF(W24="","",ROW()-6)
C25: FALSE | F25: =IF(G25="","",ROW()-9) -> 16 | G25: פרטי העסק | H25: אתר אינטרנט | I25: שדה הייפר קישור | J25: FALSE | M25: מפתח / מנהל מערכת, בעל/ת המשרד, מנהל צוות, מנהל/ת חשבונות, חשב/ת שכר, יועץ/ת מס, מתמחה, מנהל/ת משרד, "צופה / רו""ח חיצוני", לקוח (פורטל) | N25: מפתח / מנהל מערכת, בעל/ת המשרד, מנהל צוות, מנהל/ת משרד | V25: =IF(W25="","",ROW()-6)
C26: FALSE | F26: =IF(G26="","",ROW()-9) -> 17 | G26: פרטי העסק | H26: תיאור פעילות העסק | I26: איזור שדה טקסט | J26: FALSE | M26: מפתח / מנהל מערכת, בעל/ת המשרד, מנהל צוות, מנהל/ת חשבונות, חשב/ת שכר, יועץ/ת מס, מתמחה, מנהל/ת משרד, "צופה / רו""ח חיצוני", לקוח (פורטל) | N26: מפתח / מנהל מערכת, בעל/ת המשרד, מנהל צוות, מנהל/ת משרד | V26: =IF(W26="","",ROW()-6)
C27: FALSE | F27: =IF(G27="","",ROW()-9) -> 18 | G27: פרטי חשבון בנק | H27: שם הבנק | I27: תיבת בחירה | J27: FALSE | M27: מפתח / מנהל מערכת, בעל/ת המשרד, מנהל צוות, מנהל/ת חשבונות, חשב/ת שכר, יועץ/ת מס, מנהל/ת משרד, "צופה / רו""ח חיצוני", מערכת / אוטומציה | N27: מפתח / מנהל מערכת, בעל/ת המשרד, מנהל צוות, מנהל/ת משרד | V27: =IF(W27="","",ROW()-6)
C28: FALSE | F28: =IF(G28="","",ROW()-9) -> 19 | G28: פרטי חשבון בנק | H28: קוד הבנק | I28: תיבת בחירה | J28: FALSE | M28: מפתח / מנהל מערכת, בעל/ת המשרד, מנהל צוות, מנהל/ת חשבונות, חשב/ת שכר, יועץ/ת מס, מנהל/ת משרד, "צופה / רו""ח חיצוני", מערכת / אוטומציה | N28: מפתח / מנהל מערכת, בעל/ת המשרד, מנהל צוות, מנהל/ת משרד | V28: =IF(W28="","",ROW()-6)
C29: FALSE | F29: =IF(G29="","",ROW()-9) -> 20 | G29: פרטי חשבון בנק | H29: מס' סניף | I29: שדה טקסט | J29: FALSE | K29: מספר בלבד | M29: מפתח / מנהל מערכת, בעל/ת המשרד, מנהל צוות, מנהל/ת חשבונות, חשב/ת שכר, יועץ/ת מס, מנהל/ת משרד, "צופה / רו""ח חיצוני", מערכת / אוטומציה | N29: מפתח / מנהל מערכת, בעל/ת המשרד, מנהל צוות, מנהל/ת משרד | V29: =IF(W29="","",ROW()-6)
C30: FALSE | F30: =IF(G30="","",ROW()-9) -> 21 | G30: פרטי חשבון בנק | H30: מס' חשבון | I30: שדה טקסט | J30: FALSE | K30: מספר בלבד | M30: מפתח / מנהל מערכת, בעל/ת המשרד, מנהל צוות, מנהל/ת חשבונות, חשב/ת שכר, יועץ/ת מס, מנהל/ת משרד, "צופה / רו""ח חיצוני", מערכת / אוטומציה | N30: מפתח / מנהל מערכת, בעל/ת המשרד, מנהל צוות, מנהל/ת משרד | V30: =IF(W30="","",ROW()-6)
F31: =IF(G31="","",ROW()-9) -> 22 | G31: פרטי חשבון בנק | H31: שם בעל החשבון | I31: שדה טקסט | J31: FALSE | M31: מפתח / מנהל מערכת, בעל/ת המשרד, מנהל צוות, מנהל/ת חשבונות, חשב/ת שכר, יועץ/ת מס, מנהל/ת משרד, "צופה / רו""ח חיצוני", מערכת / אוטומציה | N31: מפתח / מנהל מערכת, בעל/ת המשרד, מנהל צוות, מנהל/ת משרד | V31: =IF(W31="","",ROW()-6)
F32: =IF(G32="","",ROW()-9) -> 23 | G32: פרטי חשבון בנק | H32: ייעוד | I32: תיבת בחירה | J32: FALSE | K32: כל הסוגים ואחר | M32: מפתח / מנהל מערכת, בעל/ת המשרד, מנהל צוות, מנהל/ת חשבונות, חשב/ת שכר, יועץ/ת מס, מנהל/ת משרד, "צופה / רו""ח חיצוני", מערכת / אוטומציה | N32: מפתח / מנהל מערכת, בעל/ת המשרד, מנהל צוות, מנהל/ת משרד | V32: =IF(W32="","",ROW()-6)
F33: =IF(G33="","",ROW()-9) -> 24 | G33: פרטי חשבון בנק | H33: הערות | I33: איזור שדה טקסט | J33: FALSE | M33: מפתח / מנהל מערכת, בעל/ת המשרד, מנהל צוות, מנהל/ת חשבונות, חשב/ת שכר, יועץ/ת מס, מנהל/ת משרד, "צופה / רו""ח חיצוני", מערכת / אוטומציה | N33: מפתח / מנהל מערכת, בעל/ת המשרד, מנהל צוות, מנהל/ת משרד | V33: =IF(W33="","",ROW()-6)
F34: =IF(G34="","",ROW()-6) -> 28 | G34: פרטי חשבון בנק | H34: תגיות | I34: בחירה מרובה חופשית | J34: FALSE | M34: מפתח / מנהל מערכת, בעל/ת המשרד, מנהל צוות, מנהל/ת חשבונות, חשב/ת שכר, יועץ/ת מס, מנהל/ת משרד, "צופה / רו""ח חיצוני", מערכת / אוטומציה | N34: מפתח / מנהל מערכת, בעל/ת המשרד, מנהל צוות, מנהל/ת משרד | V34: =IF(W34="","",ROW()-6)
F35: =IF(G35="","",ROW()-9) -> 26 | G35: פרטי יישות משפטית | H35: שם העסק (מוכר ברשוייות) | I35: שדה טקסט | J35: TRUE | L35: בשונה משם העסק שהוא שם ממתוג | M35: מפתח / מנהל מערכת, בעל/ת המשרד, מנהל צוות, מנהל/ת חשבונות, חשב/ת שכר, יועץ/ת מס, מתמחה, מנהל/ת משרד, "צופה / רו""ח חיצוני" | N35: מפתח / מנהל מערכת, בעל/ת המשרד, מנהל/ת משרד | V35: =IF(W35="","",ROW()-6)
F36: =IF(G36="","",ROW()-9) -> 27 | G36: פרטי יישות משפטית | H36: סוג יישות משפטית | I36: קישור למופע אחר | J36: TRUE | K36: יישות לקישור בק אנד למופע שנושא את היישות הרלוונטית | M36: מפתח / מנהל מערכת, בעל/ת המשרד, מנהל צוות, מנהל/ת חשבונות, חשב/ת שכר, יועץ/ת מס, מתמחה, מנהל/ת משרד, "צופה / רו""ח חיצוני" | N36: מפתח / מנהל מערכת, בעל/ת המשרד, מנהל/ת משרד | V36: =IF(W36="","",ROW()-6)
F37: =IF(G37="","",ROW()-9) -> 28 | G37: פרטי יישות משפטית | H37: תחום עיסוק | I37: בחירה מרובה חופשית | J37: FALSE | K37: כל תחומי העיסוק | M37: מפתח / מנהל מערכת, בעל/ת המשרד, מנהל צוות, מנהל/ת חשבונות, חשב/ת שכר, יועץ/ת מס, מתמחה, מנהל/ת משרד, "צופה / רו""ח חיצוני" | N37: מפתח / מנהל מערכת, בעל/ת המשרד, מנהל/ת משרד | V37: =IF(W37="","",ROW()-6)
F38: =IF(G38="","",ROW()-9) -> 29 | G38: פרטי יישות משפטית | H38: תת תחום | I38: איזור שדה טקסט | J38: FALSE | K38: פירוט | M38: מפתח / מנהל מערכת, בעל/ת המשרד, מנהל צוות, מנהל/ת חשבונות, חשב/ת שכר, יועץ/ת מס, מתמחה, מנהל/ת משרד, "צופה / רו""ח חיצוני" | N38: מפתח / מנהל מערכת, בעל/ת המשרד, מנהל/ת משרד | V38: =IF(W38="","",ROW()-6)
F39: =IF(G39="","",ROW()-9) -> 30 | G39: פרטי יישות משפטית | H39: תאריך פתיחת עסק | I39: שדה תאריך/זמן | J39: FALSE | M39: מפתח / מנהל מערכת, בעל/ת המשרד, מנהל צוות, מנהל/ת חשבונות, חשב/ת שכר, יועץ/ת מס, מתמחה, מנהל/ת משרד, "צופה / רו""ח חיצוני" | N39: מפתח / מנהל מערכת, בעל/ת המשרד, מנהל/ת משרד | V39: =IF(W39="","",ROW()-6)
F40: =IF(G40="","",ROW()-9) -> 31 | G40: פרטי יישות משפטית | H40: ח.פ. (מספר תיק) | I40: שדה טקסט | J40: FALSE | K40: רק מספריים | L40: וודוא כערך חד ערכי | M40: מפתח / מנהל מערכת, בעל/ת המשרד, מנהל צוות, מנהל/ת חשבונות, חשב/ת שכר, יועץ/ת מס, מתמחה, מנהל/ת משרד, "צופה / רו""ח חיצוני" | N40: מפתח / מנהל מערכת, בעל/ת המשרד, מנהל/ת משרד | V40: =IF(W40="","",ROW()-6)
F41: =IF(G41="","",ROW()-9) -> 32 | G41: פרטי יישות משפטית | H41: קוד סיווג כלכלי | I41: שדה טקסט | J41: FALSE | M41: מפתח / מנהל מערכת, בעל/ת המשרד, מנהל צוות, מנהל/ת חשבונות, חשב/ת שכר, יועץ/ת מס, מתמחה, מנהל/ת משרד, "צופה / רו""ח חיצוני" | N41: מפתח / מנהל מערכת, בעל/ת המשרד, מנהל/ת משרד | V41: =IF(W41="","",ROW()-6)
...

Sheet רשימות
A1: סוגי שדות (אוריגמי) | B1: חובה / רשות | C1: סוג טריגר | D1: פרטי טריגר | E1: פעולה מבוצעת | F1: סטטוס איפיון | G1: קבוצות משתמשים
A2: שדה טקסט | B2: חובה | C2: מופע או שדה | D2: בעת יצירת המופע | E2: הצג הודעה למשתמש | F2: רעיון | G2: מפתח / מנהל מערכת
A3: תיבת בחירה | B3: רשות | C3: כפתורי פעולה | D3: בעת עדכון שדה | E3: אוטומציה של AI | F3: באפיון | G3: בעל/ת המשרד
A4: בחירה מרובה | C4: התניה מתוזמנת | D4: בעת מחיקת מופע | E4: אפקטים | F4: מאושר לבנייה | G4: מנהל צוות
A5: בחירה מרובה חופשית | D5: בעת יצירת קבוצה החוזרת על עצמה | E5: נעל קובץ | F5: נבנה באוריגמי | G5: מנהל/ת חשבונות
A6: שדה דואר אלקטרוני | D6: בעת מחיקת קבוצה החוזרת על עצמה | E6: שליחת חוזה | F6: הושלם ונבדק | G6: חשב/ת שכר
A7: צ'ק בוקס | D7: בעת צפייה במופע | E7: מלא מסמך | G7: יועץ/ת מס
A8: שדה הייפר קישור | D8: מקם את הכפתור בתצוגת מופעים | E8: התראות | G8: מתמחה
A9: שדה טלפון | D9: מקם את הכפתור בעריכת מופע | E9: צור קבוצה חוזרת חדשה | G9: מנהל/ת משרד
A10: בחירת כתובת | D10: מקם את הכפתור בקבוצת שדות | E10: העבר למופע אחר | G10: צופה / רו"ח חיצוני
A11: איזור שדה טקסט | D11: לפי הגדרת זמן (שעה / דקה / יום בשבוע) | E11: בסיס נתונים חיצוני | G11: לקוח (פורטל)
A12: WYSIWYG | E12: הצע תיקון | G12: מערכת / אוטומציה
A13: העלאת קבצים | E13: נעל/פתח
A14: שדה תאריך/זמן | E14: אימות
A15: קישור למופע אחר | E15: מחק מופע
A16: קישור למופעים מרובים | E16: ס.מ.ס
A17: בחירת משתמש | E17: עדכן שדות
A18: שדה API | E18: שכפל רשומה
A19: בחירת משתמשים מרובה | E19: ייצוא דוחות
A20: שדה מצביע | E20: קרא לשירות חיצוני
A21: בחירה מטווח מספרים | E21: עדכון מרובה
A22: מחוון בחירה | E22: בקשת אימות
A23: שדה מטא-דטא | E23: פעולת ארכיון
A24: שדה נוסחה | E24: שלח אימייל
... A26: שדה חבוי | E26: פתח חלון חדש
A27: בחירת זמן
A28: שדה חתימה
A29: שדה סיסמא
A30: בחירת צלמית
A31: בחירת צבע

Sheet קטלוג שירותים
G1: מעבר לדף הבית | H1: מעבר מהיר לגיליון: | I1: לקוחות | J1: אנשי קשר | L1: מעבר לתהליכי עבודה | U1: מעבר לטבלת השדות | W1: מעבר לדף הבית | X1: מעבר מהיר לגיליון: | Y1: DFA | Z1: =VLOOKUP(Y1,'אינדקס'!B13:C91,2) -> פתח גיליון
F2: =CONCATENATE("🎯 מטרות-העל: ", 'אינדקס'!$B$5) -> 🎯 מטרות-העל: https://docs.google.com/open?id=16lBROr6DmzGS3AaRedcxxBk5nYQMegngfhrp90Jz1JQ | V2: =CONCATENATE("🎯 מטרות-העל: ", 'אינדקס'!$B$5) -> 🎯 מטרות-העל: https://docs.google.com/open?id=16lBROr6DmzGS3AaRedcxxBk5nYQMegngfhrp90Jz1JQ
F4: =IF(G4="","",ROW()-6) | T4: =IF(U4="","",ROW()-6) | V4: =IF(W4="","",ROW()-6)
F5: =IF(G5="","",ROW()-6) | T5: =IF(U5="","",ROW()-6) | V5: =IF(W5="","",ROW()-6)
F6: =IF(G6="","",ROW()-6) | T6: =IF(U6="","",ROW()-6) | V6: =IF(W6="","",ROW()-6)
F7: =IF(G7="","",ROW()-6) | T7: =IF(U7="","",ROW()-6) | V7: =IF(W7="","",ROW()-6)
F9: # | G9: קבוצת שדות | H9: שם שדה | I9: סוג שדה | J9: חובה/רשות | K9: ערכים אפשריים | L9: הערות | M9: הרשאות צפייה | N9: הרשאות עריכה | T9: # | U9: שם התהליך | V9: סוג טריגר | W9: פרטי טריגר | X9: תנאי הפעלה (שדה+לוגיקה) | Y9: סטטוס איפיון | Z9: הערות | AC9: שם תהליך | AD9: סוג פעולה | AE9: תיואר פעולה קצר | AF9: תיאור מפורט
B10: שם קבוצה | C10: חוזת או לא | F10: =IF(G10="","",ROW()-9) -> 1 | G10: פרטי השירות | H10: שם השירות | I10: שדה טקסט | J10: FALSE | T10: =IF(U10="","",ROW()-6)
B11: פרטי השירות | C11: FALSE | F11: =IF(G11="","",ROW()-9) -> 2 | G11: פרטי השירות | H11: חובות שהשירות מפעיל | I11: קישור למופע אחר | J11: FALSE | T11: =IF(U11="","",ROW()-6)
B12: תנאי השירות | C12: TRUE | F12: =IF(G12="","",ROW()-9) -> 3 | G12: פרטי השירות | H12: קישור לסוג לקוח שמתאים | I12: קישור למופע אחר | J12: FALSE | T12: =IF(U12="","",ROW()-6)
C13: FALSE | F13: =IF(G13="","",ROW()-9) -> 4 | G13: פרטי השירות | H13: תיאור השירות | I13: איזור שדה טקסט | J13: FALSE | T13: =IF(U13="","",ROW()-6)
C14: FALSE | F14: =IF(G14="","",ROW()-9) -> 5 | G14: תנאי השירות | J14: FALSE | T14: =IF(U14="","",ROW()-6)
C15: FALSE | F15: =IF(G15="","",ROW()-9) | J15: FALSE | T15: =IF(U15="","",ROW()-6)
C16: FALSE | F16: =IF(G16="","",ROW()-9) | J16: FALSE | T16: =IF(U16="","",ROW()-6)
C17: FALSE | F17: =IF(G17="","",ROW()-9) | J17: FALSE | T17: =IF(U17="","",ROW()-6)
C18: FALSE | F18: =IF(G18="","",ROW()-9) | J18: FALSE | T18: =IF(U18="","",ROW()-6)
C19: FALSE | F19: =IF(G19="","",ROW()-9) | J19: FALSE | T19: =IF(U19="","",ROW()-6)
C20: FALSE | F20: =IF(G20="","",ROW()-9) | J20: FALSE | T20: =IF(U20="","",ROW()-6)
C21: FALSE | F21: =IF(G21="","",ROW()-9) | J21: FALSE | T21: =IF(U21="","",ROW()-6)
C22: FALSE | F22: =IF(G22="","",ROW()-9) | J22: FALSE | T22: =IF(U22="","",ROW()-6)
C23: FALSE | F23: =IF(G23="","",ROW()-9) | J23: FALSE | T23: =IF(U23="","",ROW()-6)
C24: FALSE | F24: =IF(G24="","",ROW()-9) | J24: FALSE | T24: =IF(U24="","",ROW()-6)
C25: FALSE | F25: =IF(G25="","",ROW()-9) | J25: FALSE | T25: =IF(U25="","",ROW()-6)
C26: FALSE | F26: =IF(G26="","",ROW()-9) | J26: FALSE | T26: =IF(U26="","",ROW()-6)
... C30: FALSE | F30: =IF(G30="","",ROW()-9) | J30: FALSE | T30: =IF(U30="","",ROW()-6)
F31: =IF(G31="","",ROW()-9) | J31: FALSE | T31: =IF(U31="","",ROW()-6)
F32: =IF(G32="","",ROW()-9) | J32: FALSE | T32: =IF(U32="","",ROW()-6)
F33: =IF(G33="","",ROW()-9) | J33: FALSE | T33: =IF(U33="","",ROW()-6)
F34: =IF(G34="","",ROW()-9) | J34: FALSE | T34: =IF(U34="","",ROW()-6)
F35: =IF(G35="","",ROW()-9) | J35: FALSE | T35: =IF(U35="","",ROW()-6)
F36: =IF(G36="","",ROW()-9) | J36: FALSE | T36: =IF(U36="","",ROW()-6)
F37: =IF(G37="","",ROW()-9) | J37: FALSE | T37: =IF(U37="","",ROW()-6)
F38: =IF(G38="","",ROW()-9) | J38: FALSE | T38: =IF(U38="","",ROW()-6)
F39: =IF(G39="","",ROW()-9) | J39: FALSE | T39: =IF(U39="","",ROW()-6)
F40: =IF(G40="","",ROW()-9) | J40: FALSE | T40: =IF(U40="","",ROW()-6)
F41: =IF(G41="","",ROW()-9) | J41: FALSE | T41: =IF(U41="","",ROW()-6)
F42: =IF(G42="","",ROW()-9) | J42: FALSE | T42: =IF(U42="","",ROW()-6)
... F69: =IF(G69="","",ROW()-9) | J69: FALSE | T69: =IF(U69="","",ROW()-6)
F70: =IF(G70="","",ROW()-6) | J70: FALSE | T70: =IF(U70="","",ROW()-6)
F71: =IF(G71="","",ROW()-6) | J71: FALSE | T71: =IF(U71="","",ROW()-6)
...

Sheet עסקאות
G1: מעבר לדף הבית | H1: מעבר מהיר לגיליון: | I1: אישורים והוראות לקוח | J1: =VLOOKUP(I1,'אינדקס'!B13:C91,2) -> #N/A | L1: מעבר לתהליכי עבודה | U1: מעבר לטבלת השדות | W1: מעבר לדף הבית | X1: מעבר מהיר לגיליון: | Y1: DFA | Z1: =VLOOKUP(Y1,'אינדקס'!B13:C91,2) -> פתח גיליון
V2: =CONCATENATE("🎯 מטרות-העל: ", 'אינדקס'!$B$5) -> 🎯 מטרות-העל: https://docs.google.com/open?id=16lBROr6DmzGS3AaRedcxxBk5nYQMegngfhrp90Jz1JQ
F4: =IF(G4="","",ROW()-6) | T4: =IF(U4="","",ROW()-6) | V4: =IF(W4="","",ROW()-6)
F5: =IF(G5="","",ROW()-6) | T5: =IF(U5="","",ROW()-6) | V5: =IF(W5="","",ROW()-6)
F6: =IF(G6="","",ROW()-6) | T6: =IF(U6="","",ROW()-6) | V6: =IF(W6="","",ROW()-6)
F7: =IF(G7="","",ROW()-6) | T7: =IF(U7="","",ROW()-6) | V7: =IF(W7="","",ROW()-6)
F9: # | G9: קבוצת שדות | H9: שם שדה | I9: סוג שדה | J9: חובה/רשות | K9: ערכים אפשריים | L9: הערות | M9: הרשאות צפייה | N9: הרשאות עריכה | T9: # | U9: שם התהליך | V9: סוג טריגר | W9: פרטי טריגר | X9: תנאי הפעלה (שדה+לוגיקה) | Y9: סטטוס איפיון | Z9: הערות | AC9: שם תהליך | AD9: סוג פעולה | AE9: תיואר פעולה קצר | AF9: תיאור מפורט
B10: שם קבוצה | C10: חוזת או לא | F10: =IF(G10="","",ROW()-9) -> 1 | G10: פרטי עסקה | H10: לקוח | I10: קישור למופע אחר | J10: FALSE | T10: =IF(U10="","",ROW()-6)
B11: פרטי עסקה | C11: FALSE | F11: =IF(G11="","",ROW()-9) -> 2 | G11: פרטי עסקה | H11: תאריך חתימה | I11: שדה תאריך/זמן | J11: FALSE | T11: =IF(U11="","",ROW()-6)
B12: שירותים | C12: TRUE | F12: =IF(G12="","",ROW()-9) -> 3 | G12: פרטי עסקה | H12: בתוקף עד | I12: שדה תאריך/זמן | J12: FALSE | T12: =IF(U12="","",ROW()-6)
B13: הערות לעסקה | C13: TRUE | F13: =IF(G13="","",ROW()-9) -> 4 | G13: פרטי עסקה | H13: סטטוס מחושב | I13: שדה נוסחה | J13: FALSE | T13: =IF(U13="","",ROW()-6)
C14: FALSE | F14: =IF(G14="","",ROW()-9) -> 5 | G14: פרטי עסקה | H14: סטטוס | I14: תיבת בחירה | J14: FALSE | T14: =IF(U14="","",ROW()-6)
C15: FALSE | F15: =IF(G15="","",ROW()-9) -> 6 | G15: פרטי עסקה | H15: חוזה שירות | I15: קישור למופע אחר | J15: FALSE | K15: מסמכים | T15: =IF(U15="","",ROW()-6)
C16: FALSE | F16: =IF(G16="","",ROW()-9) -> 7 | G16: פרטי עסקה | H16: מחיר עסקה מוחשב לפני מע"מ | I16: שדה נוסחה | J16: FALSE | T16: =IF(U16="","",ROW()-6)
C17: FALSE | F17: =IF(G17="","",ROW()-9) -> 8 | G17: פרטי עסקה | H17: הנחה כללית | I17: שדה טקסט | J17: FALSE | T17: =IF(U17="","",ROW()-6)
C18: FALSE | F18: =IF(G18="","",ROW()-9) -> 9 | G18: פרטי עסקה | H18: מחיר אחרי מע"מ | I18: שדה נוסחה | J18: FALSE | T18: =IF(U18="","",ROW()-6)
C19: FALSE | F19: =IF(G19="","",ROW()-9) -> 10 | G19: פרטי עסקה | H19: קישור לתשלומים | J19: FALSE | T19: =IF(U19="","",ROW()-6)
C20: FALSE | F20: =IF(G20="","",ROW()-9) -> 11 | G20: פרטי עסקה | H20: מודל תמחור | J20: FALSE | T20: =IF(U20="","",ROW()-6)
C21: FALSE | F21: =IF(G21="","",ROW()-9) -> 12 | G21: פרטי עסקה | H21: מעקב תשלום | J21: FALSE | T21: =IF(U21="","",ROW()-6)
C22: FALSE | F22: =IF(G22="","",ROW()-9) -> 13 | G22: שירותים | H22: קישור לשירות | I22: קישור למופע אחר | J22: FALSE | T22: =IF(U22="","",ROW()-6)
C23: FALSE | F23: =IF(G23="","",ROW()-9) -> 14 | G23: שירותים | H23: מחיר שירות | I23: שדה מצביע | J23: FALSE | T23: =IF(U23="","",ROW()-6)
C24: FALSE | F24: =IF(G24="","",ROW()-9) -> 15 | G24: שירותים | H24: כמות | I24: שדה טקסט | J24: FALSE | T24: =IF(U24="","",ROW()-6)
C25: FALSE | F25: =IF(G25="","",ROW()-9) -> 16 | G25: שירותים | H25: הנחה | I25: שדה טקסט | J25: FALSE | T25: =IF(U25="","",ROW()-6)
C26: FALSE | F26: =IF(G26="","",ROW()-9) -> 17 | G26: שירותים | H26: מחיר לפני מע"מ | I26: שדה נוסחה | J26: FALSE | T26: =IF(U26="","",ROW()-6)
C27: FALSE | F27: =IF(G27="","",ROW()-9) -> 18 | G27: שירותים | H27: מחיר אחרי מע"מ | I27: שדה נוסחה | J27: FALSE | T27: =IF(U27="","",ROW()-6)
C28: FALSE | F28: =IF(G28="","",ROW()-9) -> 19 | G28: שירותים | H28: תיאור השירות | I28: שדה מצביע | J28: FALSE | T28: =IF(U28="","",ROW()-6)
C29: FALSE | F29: =IF(H29="","",ROW()-9) -> 20 | G29: הערות לעסקה | H29: הערות לעסקה | I29: איזור שדה טקסט | J29: FALSE | T29: =IF(U29="","",ROW()-6)
C30: FALSE | F30: =IF(G30="","",ROW()-9) -> 21 | G30: הערות לעסקה | H30: תאריך | I30: שדה תאריך/זמן | J30: FALSE | T30: =IF(U30="","",ROW()-6)
F31: =IF(G31="","",ROW()-9) -> 22 | G31: הערות לעסקה | H31: בתוקף עד | I31: שדה תאריך/זמן | J31: FALSE | T31: =IF(U31="","",ROW()-6)
F32: =IF(G32="","",ROW()-9) -> 23 | G32: הערות לעסקה | H32: יוצר | I32: בחירת משתמש | J32: FALSE | T32: =IF(U32="","",ROW()-6)
F33: =IF(G33="","",ROW()-9) -> 24 | G33: פרטי עסקה | H33: ס"ה עובדים של לקוח | I33: שדה נוסחה | J33: FALSE | T33: =IF(U33="","",ROW()-6)
F34: =IF(G34="","",ROW()-9) -> 25 | G34: שירותים | H34: תקף? | I34: שדה נוסחה | J34: FALSE | T34: =IF(U34="","",ROW()-6)
F35: =IF(G35="","",ROW()-9) -> 26 | G35: שירותים | H35: מחיר הצעה לפני מע"מ | I35: שדה מצביע | J35: FALSE | T35: =IF(U35="","",ROW()-6)
F36: =IF(G36="","",ROW()-9) -> 27 | G36: שירותים | H36: מחיר הצעה אחרי מע"מ | I36: שדה נוסחה | J36: FALSE | T36: =IF(U36="","",ROW()-6)
F37: =IF(G37="","",ROW()-9) -> 28 | G37: שירותים | H37: בתוקף מ | I37: שדה תאריך/זמן | J37: FALSE | T37: =IF(U37="","",ROW()-6)
F38: =IF(G38="","",ROW()-9) -> 29 | G38: שירותים | H38: בתוקף עד | I38: שדה תאריך/זמן | J38: FALSE | T38: =IF(U38="","",ROW()-6)
F39: =IF(G39="","",ROW()-9) | J39: FALSE | T39: =IF(U39="","",ROW()-6)
F40: =IF(G40="","",ROW()-9) | J40: FALSE | T40: =IF(U40="","",ROW()-6)
F41: =IF(G41="","",ROW()-9) | J41: FALSE | T41: =IF(U41="","",ROW()-6)
F42: =IF(G42="","",ROW()-9) | J42: FALSE | T42: =IF(U42="","",ROW()-6)
...

Sheet תקשורת
G1: מעבר לדף הבית | H1: מעבר מהיר לגיליון: | I1: ZDSFA | J1: =VLOOKUP(I1,'אינדקס'!B13:C91,2) -> פתח גיליון | L1: מעבר לתהליכי עבודה | U1: מעבר לטבלת השדות | W1: מעבר לדף הבית | X1: מעבר מהיר לגיליון: | Y1: DFA | Z1: =VLOOKUP(Y1,'אינדקס'!B13:C91,2) -> פתח גיליון
F2: =CONCATENATE("🎯 מטרות-העל: ", 'אינדקס'!$B$5) -> 🎯 מטרות-העל: https://docs.google.com/open?id=16lBROr6DmzGS3AaRedcxxBk5nYQMegngfhrp90Jz1JQ | V2: =CONCATENATE("🎯 מטרות-העל: ", 'אינדקס'!$B$5) -> 🎯 מטרות-העל: https://docs.google.com/open?id=16lBROr6DmzGS3AaRedcxxBk5nYQMegngfhrp90Jz1JQ
F4: =IF(G4="","",ROW()-6) | T4: =IF(U4="","",ROW()-6) | V4: =IF(W4="","",ROW()-6)
F5: =IF(G5="","",ROW()-6) | T5: =IF(U5="","",ROW()-6) | V5: =IF(W5="","",ROW()-6)
F6: =IF(G6="","",ROW()-6) | T6: =IF(U6="","",ROW()-6) | V6: =IF(W6="","",ROW()-6)
F7: =IF(G7="","",ROW()-6) | T7: =IF(U7="","",ROW()-6) | V7: =IF(W7="","",ROW()-6)
F9: # | G9: קבוצת שדות | H9: שם שדה | I9: סוג שדה | J9: חובה/רשות | K9: ערכים אפשריים | L9: הערות | M9: הרשאות צפייה | N9: הרשאות עריכה | T9: # | U9: שם התהליך | V9: סוג טריגר | W9: פרטי טריגר | X9: תנאי הפעלה (שדה+לוגיקה) | Y9: סטטוס איפיון | Z9: הערות | AC9: שם תהליך | AD9: סוג פעולה | AE9: תיואר פעולה קצר | AF9: תיאור מפורט
B10: שם קבוצה | C10: חוזת או לא | F10: =IF(G10="","",ROW()-9) -> 1 | G10: התקשורת | H10: לקוח | I10: קישור למופע אחר | J10: FALSE | T10: =IF(U10="","",ROW()-6)
B11: התקשורת | C11: FALSE | F11: =IF(G11="","",ROW()-9) -> 2 | G11: התקשורת | H11: איש קשר | I11: קישור למופע אחר | J11: FALSE | T11: =IF(U11="","",ROW()-6)
C12: FALSE | F12: =IF(G12="","",ROW()-9) -> 3 | G12: התקשורת | H12: עובד משרד | I12: קישור למופע אחר | J12: FALSE | T12: =IF(U12="","",ROW()-6)
C13: FALSE | F13: =IF(G13="","",ROW()-9) -> 4 | G13: התקשורת | H13: סוג תקשורת | I13: תיבת בחירה | J13: FALSE | T13: =IF(U13="","",ROW()-6)
C14: FALSE | F14: =IF(G14="","",ROW()-9) -> 5 | G14: התקשורת | H14: חותמת זמן | I14: שדה תאריך/זמן | J14: FALSE | T14: =IF(U14="","",ROW()-6)
C15: FALSE | F15: =IF(G15="","",ROW()-9) -> 6 | G15: התקשורת | H15: סיכום | I15: איזור שדה טקסט | J15: FALSE | T15: =IF(U15="","",ROW()-6)
C16: FALSE | F16: =IF(G16="","",ROW()-9) -> 7 | G16: התקשורת | H16: מסמכים מקושרים | I16: קישור למופע אחר | J16: FALSE | T16: =IF(U16="","",ROW()-6)
C17: FALSE | F17: =IF(G17="","",ROW()-9) -> 8 | G17: התקשורת | H17: הקלטה | I17: קישור למופע אחר | J17: FALSE | T17: =IF(U17="","",ROW()-6)
C18: FALSE | F18: =IF(G18="","",ROW()-9) | J18: FALSE | T18: =IF(U18="","",ROW()-6)
C19: FALSE | F19: =IF(G19="","",ROW()-9) | J19: FALSE | T19: =IF(U19="","",ROW()-6)
C20: FALSE | F20: =IF(G20="","",ROW()-9) | J20: FALSE | T20: =IF(U20="","",ROW()-6)
C21: FALSE | F21: =IF(G21="","",ROW()-9) | J21: FALSE | T21: =IF(U21="","",ROW()-6)
C22: FALSE | F22: =IF(G22="","",ROW()-9) | J22: FALSE | T22: =IF(U22="","",ROW()-6)
C23: FALSE | F23: =IF(G23="","",ROW()-9) | J23: FALSE | T23: =IF(U23="","",ROW()-6)
C24: FALSE | F24: =IF(G24="","",ROW()-9) | J24: FALSE | T24: =IF(U24="","",ROW()-6)
C25: FALSE | F25: =IF(G25="","",ROW()-9) | J25: FALSE | T25: =IF(U25="","",ROW()-6)
C26: FALSE | F26: =IF(G26="","",ROW()-9) | J26: FALSE | T26: =IF(U26="","",ROW()-6)
C27: FALSE | F27: =IF(G27="","",ROW()-9) | J27: FALSE | T27: =IF(U27="","",ROW()-6)
C28: FALSE | F28: =IF(G28="","",ROW()-9) | J28: FALSE | T28: =IF(U28="","",ROW()-6)
C29: FALSE | F29: =IF(G29="","",ROW()-9) | J29: FALSE | T29: =IF(U29="","",ROW()-6)
C30: FALSE | F30: =IF(G30="","",ROW()-9) | J30: FALSE | T30: =IF(U30="","",ROW()-6)
F31: =IF(G31="","",ROW()-9) | J31: FALSE | T31: =IF(U31="","",ROW()-6)
F32: =IF(G32="","",ROW()-9) | J32: FALSE | T32: =IF(U32="","",ROW()-6)
F33: =IF(G33="","",ROW()-9) | J33: FALSE | T33: =IF(U33="","",ROW()-6)
F34: =IF(G34="","",ROW()-9) | J34: FALSE | T34: =IF(U34="","",ROW()-6)
F35: =IF(G35="","",ROW()-9) | J35: FALSE | T35: =IF(U35="","",ROW()-6)
F36: =IF(G36="","",ROW()-9) | J36: FALSE | T36: =IF(U36="","",ROW()-6)
F37: =IF(G37="","",ROW()-9) | J37: FALSE | T37: =IF(U37="","",ROW()-6)
F38: =IF(G38="","",ROW()-9) | J38: FALSE | T38: =IF(U38="","",ROW()-6)
F39: =IF(G39="","",ROW()-9) | J39: FALSE | T39: =IF(U39="","",ROW()-6)
F40: =IF(G40="","",ROW()-9) | J40: FALSE | T40: =IF(U40="","",ROW()-6)
F41: =IF(G41="","",ROW()-9) | J41: FALSE | T41: =IF(U41="","",ROW()-6)
F42: =IF(G42="","",ROW()-9) | J42: FALSE | T42: =IF(U42="","",ROW()-6)
...

Sheet משימות
G1: מעבר לדף הבית | H1: מעבר מהיר לגיליון: | I1: לקוחות | J1: אנשי קשר | L1: מעבר לתהליכי עבודה | U1: מעבר לטבלת השדות | W1: מעבר לדף הבית | X1: מעבר מהיר לגיליון: | Y1: DFA | Z1: =VLOOKUP(Y1,'אינדקס'!B13:C91,2) -> פתח גיליון
F2: =CONCATENATE("🎯 מטרות-העל: ", 'אינדקס'!$B$5) -> 🎯 מטרות-העל: https://docs.google.com/open?id=16lBROr6DmzGS3AaRedcxxBk5nYQMegngfhrp90Jz1JQ | V2: =CONCATENATE("🎯 מטרות-העל: ", 'אינדקס'!$B$5) -> 🎯 מטרות-העל: https://docs.google.com/open?id=16lBROr6DmzGS3AaRedcxxBk5nYQMegngfhrp90Jz1JQ
F4: =IF(G4="","",ROW()-6) | T4: =IF(U4="","",ROW()-6) | V4: =IF(W4="","",ROW()-6)
F5: =IF(G5="","",ROW()-6) | T5: =IF(U5="","",ROW()-6) | V5: =IF(W5="","",ROW()-6)
F6: =IF(G6="","",ROW()-6) | T6: =IF(U6="","",ROW()-6) | V6: =IF(W6="","",ROW()-6)
F7: =IF(G7="","",ROW()-6) | T7: =IF(U7="","",ROW()-6) | V7: =IF(W7="","",ROW()-6)
F9: # | G9: קבוצת שדות | H9: שם שדה | I9: סוג שדה | J9: חובה/רשות | K9: ערכים אפשריים | L9: הערות | M9: הרשאות צפייה | N9: הרשאות עריכה | T9: # | U9: שם התהליך | V9: סוג טריגר | W9: פרטי טריגר | X9: תנאי הפעלה (שדה+לוגיקה) | Y9: סטטוס איפיון | Z9: הערות | AC9: שם תהליך | AD9: סוג פעולה | AE9: תיואר פעולה קצר | AF9: תיאור מפורט
B10: שם קבוצה | C10: חוזת או לא | F10: =IF(G10="","",ROW()-9) -> 1 | G10: הערכת זמן | H10: תאריך יצירה | I10: שדה תאריך/זמן | J10: FALSE | T10: =IF(U10="","",ROW()-6)
B11: פרטי המשימה | C11: FALSE | F11: =IF(G11="","",ROW()-9) -> 2 | G11: הערכת זמן | H11: תאריך יעד | I11: שדה תאריך/זמן | J11: FALSE | T11: =IF(U11="","",ROW()-6)
B12: ציק ליסט | C12: FALSE | F12: =IF(G12="","",ROW()-9) -> 3 | G12: הערכת זמן | H12: תאריך סיום בפועל | I12: שדה תאריך/זמן | J12: FALSE | T12: =IF(U12="","",ROW()-6)
B13: הערכת זמן | C13: FALSE | F13: =IF(G13="","",ROW()-9) -> 4 | G13: הערכת זמן | H13: תאריך התחלה בפועל | I13: שדה תאריך/זמן | J13: FALSE | T13: =IF(U13="","",ROW()-6)
B14: התקדמות | C14: FALSE | F14: =IF(G14="","",ROW()-9) -> 5 | G14: הערכת זמן | H14: הערכת זמן | I14: שדה תאריך/זמן | J14: FALSE | T14: =IF(U14="","",ROW()-6)
B15: הסטוריה | C15: FALSE | F15: =IF(G15="","",ROW()-9) -> 6 | G15: הערכת זמן | H15: זמן בפועל | I15: שדה נוסחה | J15: FALSE | T15: =IF(U15="","",ROW()-6)
C16: FALSE | F16: =IF(G16="","",ROW()-9) -> 7 | G16: הערכת זמן | H16: סטייה | I16: שדה נוסחה | J16: FALSE | T16: =IF(U16="","",ROW()-6)
C17: FALSE | F17: =IF(G17="","",ROW()-9) -> 8 | G17: הערכת זמן | H17: זמן מחזור | I17: שדה טקסט | J17: FALSE | T17: =IF(U17="","",ROW()-6)
C18: FALSE | F18: =IF(G18="","",ROW()-9) -> 9 | G18: התקדמות | H18: מטלת אב | I18: קישור למופע אחר | J18: FALSE | T18: =IF(U18="","",ROW()-6)
C19: FALSE | F19: =IF(G19="","",ROW()-9) -> 10 | G19: התקדמות | H19: תלויה במטלה | I19: קישור למופע אחר | J19: FALSE | T19: =IF(U19="","",ROW()-6)
C20: FALSE | F20: =IF(G20="","",ROW()-9) -> 11 | G20: התקדמות | H20: מטלות בנות | I20: קישור למופע אחר | J20: FALSE | T20: =IF(U20="","",ROW()-6)
C21: FALSE | F21: =IF(G21="","",ROW()-9) -> 12 | G21: התקדמות | H21: התקדמות בנות | I21: שדה נוסחה | J21: FALSE | T21: =IF(U21="","",ROW()-6)
C22: FALSE | F22: =IF(G22="","",ROW()-9) -> 13 | G22: פרטי המשימה | H22: כותרת | I22: שדה טקסט | J22: FALSE | T22: =IF(U22="","",ROW()-6)
C23: FALSE | F23: =IF(G23="","",ROW()-9) -> 14 | G23: פרטי המשימה | H23: קישור ללקוח | I23: קישור למופע אחר | J23: FALSE | T23: =IF(U23="","",ROW()-6)
C24: FALSE | F24: =IF(G24="","",ROW()-9) -> 15 | G24: פרטי המשימה | H24: עובד אחראי | I24: איזור שדה טקסט | J24: FALSE | T24: =IF(U24="","",ROW()-6)
C25: FALSE | F25: =IF(G25="","",ROW()-9) -> 16 | G25: פרטי המשימה | H25: סוג משימה | I25: קישור למופע אחר | J25: FALSE | T25: =IF(U25="","",ROW()-6)
C26: FALSE | F26: =IF(G26="","",ROW()-9) -> 17 | G26: פרטי המשימה | H26: תדירות | I26: קישור למופע אחר | J26: FALSE | T26: =IF(U26="","",ROW()-6)
C27: FALSE | F27: =IF(G27="","",ROW()-9) -> 18 | G27: פרטי המשימה | H27: ססטוס | I27: תיבת בחירה | J27: FALSE | T27: =IF(U27="","",ROW()-6)
C28: FALSE | F28: =IF(G28="","",ROW()-9) -> 19 | G28: פרטי המשימה | H28: פרטי המשימה /תיאור | I28: איזור שדה טקסט | J28: FALSE | T28: =IF(U28="","",ROW()-6)
C29: FALSE | F29: =IF(G29="","",ROW()-9) -> 20 | G29: פרטי המשימה | H29: ממתין ל | I29: קישור למופע אחר | J29: FALSE | L29: רק אםסטטוס ממתינה | T29: =IF(U29="","",ROW()-6)
C30: FALSE | F30: =IF(G30="","",ROW()-9) -> 21 | G30: פרטי המשימה | H30: ממתין מתאריך | I30: שדה תאריך/זמן | J30: FALSE | T30: =IF(U30="","",ROW()-6)
F31: =IF(G31="","",ROW()-9) -> 22 | G31: פרטי המשימה | H31: להציג מתאריך | I31: שדה תאריך/זמן | J31: FALSE | L31: רק אם סטטוס הוא נדחתה/רדומה | T31: =IF(U31="","",ROW()-6)
F32: =IF(G32="","",ROW()-9) -> 23 | G32: פרטי המשימה | H32: סיבה | I32: איזור שדה טקסט | J32: FALSE | T32: =IF(U32="","",ROW()-6)
F33: =IF(G33="","",ROW()-9) -> 24 | G33: פרטי המשימה | H33: לשלוח תזכורת | I33: צ'ק בוקס | J33: FALSE | T33: =IF(U33="","",ROW()-6)
F34: =IF(G34="","",ROW()-9) -> 25 | G34: פרטי המשימה | H34: תזכורות | I34: קישור למופע אחר | J34: FALSE | L34: רק עם סומן שילחת תזכורת | T34: =IF(U34="","",ROW()-6)
F35: =IF(G35="","",ROW()-9) -> 26 | G35: פרטי המשימה | H35: עדיפות | I35: שדה נוסחה | J35: FALSE | T35: =IF(U35="","",ROW()-6)
F36: =IF(G36="","",ROW()-9) -> 27 | G36: פרטי המשימה | H36: דחיפות | I36: שדה נוסחה | J36: FALSE | T36: =IF(U36="","",ROW()-6)
F37: =IF(G37="","",ROW()-9) -> 28 | G37: ציק ליסט | H37: תיאור | I37: איזור שדה טקסט | J37: FALSE | T37: =IF(U37="","",ROW()-6)
F38: =IF(G38="","",ROW()-9) -> 29 | G38: ציק ליסט | H38: סימון | I38: צ'ק בוקס | J38: FALSE | T38: =IF(U38="","",ROW()-6)
F39: =IF(G39="","",ROW()-9) -> 30 | G39: התקדמות | H39: פעילה היום? | I39: שדה נוסחה | J39: FALSE | T39: =IF(U39="","",ROW()-6)
F40: =IF(G40="","",ROW()-9) -> 31 | G40: התקדמות | H40: חריג | I40: שדה נוסחה | J40: FALSE | T40: =IF(U40="","",ROW()-6)
F41: =IF(G41="","",ROW()-9) -> 32 | G41: פרטי המשימה | H41: מקור המטלה | I41: קישור למופע אחר | J41: FALSE | T41: =IF(U41="","",ROW()-6)
F42: =IF(G42="","",ROW()-9) -> 33 | G42: פרטי המשימה | H42: אירוע מקור | I42: קישור למופע אחר | J42: FALSE | T42: =IF(U42="","",ROW()-6)
...

Sheet עובד משרד
G1: מעבר לדף הבית | H1: מעבר מהיר לגיליון: | I1: ZDSFA | J1: =VLOOKUP(I1,'אינדקס'!B13:C91,2) -> פתח גיליון | L1: מעבר לתהליכי עבודה | U1: מעבר לטבלת השדות | W1: מעבר לדף הבית | X1: מעבר מהיר לגיליון: | Y1: DFA | Z1: =VLOOKUP(Y1,'אינדקס'!B13:C91,2) -> פתח גיליון
F2: =CONCATENATE("🎯 מטרות-העל: ", 'אינדקס'!$B$5) -> 🎯 מטרות-העל: https://docs.google.com/open?id=16lBROr6DmzGS3AaRedcxxBk5nYQMegngfhrp90Jz1JQ | V2: =CONCATENATE("🎯 מטרות-העל: ", 'אינדקס'!$B$5) -> 🎯 מטרות-העל: https://docs.google.com/open?id=16lBROr6DmzGS3AaRedcxxBk5nYQMegngfhrp90Jz1JQ
F4: =IF(G4="","",ROW()-6) | T4: =IF(U4="","",ROW()-6) | V4: =IF(W4="","",ROW()-6)
F5: =IF(G5="","",ROW()-6) | T5: =IF(U5="","",ROW()-6) | V5: =IF(W5="","",ROW()-6)
F6: =IF(G6="","",ROW()-6) | T6: =IF(U6="","",ROW()-6) | V6: =IF(W6="","",ROW()-6)
F7: =IF(G7="","",ROW()-6) | T7: =IF(U7="","",ROW()-6) | V7: =IF(W7="","",ROW()-6)
F9: # | G9: קבוצת שדות | H9: שם שדה | I9: סוג שדה | J9: חובה/רשות | K9: ערכים אפשריים | L9: הערות | M9: הרשאות צפייה | N9: הרשאות עריכה | T9: # | U9: שם התהליך | V9: סוג טריגר | W9: פרטי טריגר | X9: תנאי הפעלה (שדה+לוגיקה) | Y9: סטטוס איפיון | Z9: הערות | AC9: שם תהליך | AD9: סוג פעולה | AE9: תיואר פעולה קצר | AF9: תיאור מפורט
B10: שם קבוצה | C10: חוזת או לא | F10: =IF(G10="","",ROW()-9) -> 1 | G10: פרטי העובד | H10: שם | I10: שדה טקסט | J10: FALSE | T10: =IF(U10="","",ROW()-6)
B11: פרטי העובד | C11: FALSE | F11: =IF(G11="","",ROW()-9) -> 2 | G11: פרטי העובד | H11: שם משפחה | I11: שדה טקסט | J11: FALSE | T11: =IF(U11="","",ROW()-6)
B12: פרטי העסקה | C12: FALSE | F12: =IF(G12="","",ROW()-9) -> 3 | G12: פרטי העובד | H12: טלפון | I12: שדה טלפון | J12: FALSE | T12: =IF(U12="","",ROW()-6)
B13: תפקידים ועיסוקים | C13: FALSE | F13: =IF(G13="","",ROW()-9) -> 4 | G13: פרטי העובד | H13: וואצאפ | I13: צ'ק בוקס | J13: FALSE | T13: =IF(U13="","",ROW()-6)
C14: FALSE | F14: =IF(G14="","",ROW()-9) -> 5 | G14: פרטי העובד | H14: אימייל | I14: שדה דואר אלקטרוני | J14: FALSE | T14: =IF(U14="","",ROW()-6)
C15: FALSE | F15: =IF(G15="","",ROW()-9) -> 6 | G15: פרטי העובד | H15: כתובת | I15: בחירת כתובת | J15: FALSE | T15: =IF(U15="","",ROW()-6)
C16: FALSE | F16: =IF(G16="","",ROW()-9) -> 7 | G16: פרטי העובד | H16: טלפון נוסף | I16: שדה טלפון | J16: FALSE | T16: =IF(U16="","",ROW()-6)
C17: FALSE | F17: =IF(G17="","",ROW()-9) -> 8 | G17: פרטי העובד | H17: הערות | I17: איזור שדה טקסט | J17: FALSE | T17: =IF(U17="","",ROW()-6)
C18: FALSE | F18: =IF(G18="","",ROW()-9) -> 9 | G18: פרטי העסקה | H18: תחילת העסקה | I18: שדה תאריך/זמן | J18: FALSE | T18: =IF(U18="","",ROW()-6)
C19: FALSE | F19: =IF(G19="","",ROW()-9) -> 10 | G19: פרטי העסקה | H19: הסכם העסקה | I19: קישור למופע אחר | J19: FALSE | T19: =IF(U19="","",ROW()-6)
C20: FALSE | F20: =IF(G20="","",ROW()-9) -> 11 | G20: פרטי העסקה | H20: עלות שעה פנימית | I20: שדה טקסט | J20: FALSE | T20: =IF(U20="","",ROW()-6)
C21: FALSE | F21: =IF(G21="","",ROW()-9) -> 12 | G21: פרטי העסקה | H21: סטטוס | I21: תיבת בחירה | J21: FALSE | T21: =IF(U21="","",ROW()-6)
C22: FALSE | F22: =IF(G22="","",ROW()-9) -> 13 | G22: פרטי העסקה | H22: זמינות | J22: FALSE | T22: =IF(U22="","",ROW()-6)
C23: FALSE | F23: =IF(G23="","",ROW()-9) -> 14 | G23: תפקידים ועיסוקים | H23: תפקיד | I23: קישור למופע אחר | J23: FALSE | T23: =IF(U23="","",ROW()-6)
C24: FALSE | F24: =IF(G24="","",ROW()-9) -> 15 | G24: תפקידים ועיסוקים | H24: התמחויות | I24: בחירה מרובה | J24: FALSE | T24: =IF(U24="","",ROW()-6)
C25: FALSE | F25: =IF(G25="","",ROW()-9) -> 16 | G25: תפקידים ועיסוקים | H25: מידע נוסף | I25: איזור שדה טקסט | J25: FALSE | T25: =IF(U25="","",ROW()-6)
C26: FALSE | F26: =IF(G26="","",ROW()-9) -> 17 | G26: תפקידים ועיסוקים | J26: FALSE | T26: =IF(U26="","",ROW()-6)
C27: FALSE | F27: =IF(G27="","",ROW()-9) | J27: FALSE | T27: =IF(U27="","",ROW()-6)
C28: FALSE | F28: =IF(G28="","",ROW()-9) | J28: FALSE | T28: =IF(U28="","",ROW()-6)
C29: FALSE | F29: =IF(G29="","",ROW()-9) | J29: FALSE | T29: =IF(U29="","",ROW()-6)
C30: FALSE | F30: =IF(G30="","",ROW()-9) | J30: FALSE | T30: =IF(U30="","",ROW()-6)
F31: =IF(G31="","",ROW()-9) | J31: FALSE | T31: =IF(U31="","",ROW()-6)
F32: =IF(G32="","",ROW()-9) | J32: FALSE | T32: =IF(U32="","",ROW()-6)
F33: =IF(G33="","",ROW()-9) | J33: FALSE | T33: =IF(U33="","",ROW()-6)
F34: =IF(G34="","",ROW()-9) | J34: FALSE | T34: =IF(U34="","",ROW()-6)
F35: =IF(G35="","",ROW()-9) | J35: FALSE | T35: =IF(U35="","",ROW()-6)
F36: =IF(G36="","",ROW()-9) | J36: FALSE | T36: =IF(U36="","",ROW()-6)
F37: =IF(G37="","",ROW()-9) | J37: FALSE | T37: =IF(U37="","",ROW()-6)
F38: =IF(G38="","",ROW()-9) | J38: FALSE | T38: =IF(U38="","",ROW()-6)
F39: =IF(G39="","",ROW()-9) | J39: FALSE | T39: =IF(U39="","",ROW()-6)
F40: =IF(G40="","",ROW()-9) | J40: FALSE | T40: =IF(U40="","",ROW()-6)
F41: =IF(G41="","",ROW()-9) | J41: FALSE | T41: =IF(U41="","",ROW()-6)
F42: =IF(G42="","",ROW()-9) | J42: FALSE | T42: =IF(U42="","",ROW()-6)
...

Sheet תבניות חובת דיווח
G1: מעבר לדף הבית | H1: מעבר מהיר לגיליון: | I1: לקוחות | J1: אנשי קשר | L1: מעבר לתהליכי עבודה | U1: מעבר לטבלת השדות | W1: מעבר לדף הבית | X1: מעבר מהיר לגיליון: | Y1: DFA | Z1: =VLOOKUP(Y1,'אינדקס'!B13:C91,2) -> פתח גיליון
F2: =CONCATENATE("🎯 מטרות-העל: ", 'אינדקס'!$B$5) -> 🎯 מטרות-העל: https://docs.google.com/open?id=16lBROr6DmzGS3AaRedcxxBk5nYQMegngfhrp90Jz1JQ | V2: =CONCATENATE("🎯 מטרות-העל: ", 'אינדקס'!$B$5) -> 🎯 מטרות-העל: https://docs.google.com/open?id=16lBROr6DmzGS3AaRedcxxBk5nYQMegngfhrp90Jz1JQ
F4: =IF(G4="","",ROW()-6) | T4: =IF(U4="","",ROW()-6) | V4: =IF(W4="","",ROW()-6)
F5: =IF(G5="","",ROW()-6) | T5: =IF(U5="","",ROW()-6) | V5: =IF(W5="","",ROW()-6)
F6: =IF(G6="","",ROW()-6) | T6: =IF(U6="","",ROW()-6) | V6: =IF(W6="","",ROW()-6)
F7: =IF(G7="","",ROW()-6) | T7: =IF(U7="","",ROW()-6) | V7: =IF(W7="","",ROW()-6)
F9: # | G9: קבוצת שדות | H9: שם שדה | I9: סוג שדה | J9: חובה/רשות | K9: ערכים אפשריים | L9: הערות | M9: הרשאות צפייה | N9: הרשאות עריכה | T9: # | U9: שם התהליך | V9: סוג טריגר | W9: פרטי טריגר | X9: תנאי הפעלה (שדה+לוגיקה) | Y9: סטטוס איפיון | Z9: הערות | AC9: שם תהליך | AD9: סוג פעולה | AE9: תיואר פעולה קצר | AF9: תיאור מפורט
B10: שם קבוצה | C10: חוזת או לא | F10: =IF(G10="","",ROW()-9) -> 1 | G10: סוג חומר נדרש | H10: שם החומר | I10: שדה טקסט | J10: FALSE | T10: =IF(U10="","",ROW()-6)
B11: פרטי החובה | C11: FALSE | F11: =IF(G11="","",ROW()-9) -> 2 | G11: סוג חומר נדרש | H11: סוג המסמך | I11: בחירה מרובה | J11: FALSE | T11: =IF(U11="","",ROW()-6)
B12: סוג חומר נדרש | C12: TRUE | F12: =IF(G12="","",ROW()-9) -> 3 | G12: סוג חומר נדרש | H12: קישור לסוגי חומרים | I12: קישור למופע אחר | J12: FALSE | T12: =IF(U12="","",ROW()-6)
C13: FALSE | F13: =IF(G13="","",ROW()-9) -> 4 | G13: סוג חומר נדרש | H13: הערות | I13: איזור שדה טקסט | J13: FALSE | T13: =IF(U13="","",ROW()-6)
C14: FALSE | F14: =IF(G14="","",ROW()-9) -> 5 | G14: פרטי החובה | H14: שם החובה | I14: שדה טקסט | J14: FALSE | T14: =IF(U14="","",ROW()-6)
C15: FALSE | F15: =IF(G15="","",ROW()-9) -> 6 | G15: פרטי החובה | H15: תדירות דיווח | I15: קישור למופע אחר | J15: FALSE | T15: =IF(U15="","",ROW()-6)
C16: FALSE | F16: =IF(G16="","",ROW()-9) -> 7 | G16: פרטי החובה | H16: שירות מפעיל | I16: קישור למופע אחר | J16: FALSE | T16: =IF(U16="","",ROW()-6)
C17: FALSE | F17: =IF(G17="","",ROW()-9) -> 8 | G17: פרטי החובה | H17: חל על סוגי ישיות | I17: שדה מצביע | J17: FALSE | T17: =IF(U17="","",ROW()-6)
C18: FALSE | F18: =IF(G18="","",ROW()-9) -> 9 | G18: פרטי החובה | H18: גרירת תשלום | I18: קישור למופע אחר | J18: FALSE | T18: =IF(U18="","",ROW()-6)
C19: FALSE | F19: =IF(G19="","",ROW()-9) -> 10 | G19: פרטי החובה | H19: תיאור החובה | I19: איזור שדה טקסט | J19: TRUE | T19: =IF(U19="","",ROW()-6)
C20: FALSE | F20: =IF(G20="","",ROW()-9) | J20: FALSE | T20: =IF(U20="","",ROW()-6)
C21: FALSE | F21: =IF(G21="","",ROW()-9) | J21: FALSE | T21: =IF(U21="","",ROW()-6)
C22: FALSE | F22: =IF(G22="","",ROW()-9) | J22: FALSE | T22: =IF(U22="","",ROW()-6)
C23: FALSE | F23: =IF(G23="","",ROW()-9) | J23: FALSE | T23: =IF(U23="","",ROW()-6)
C24: FALSE | F24: =IF(G24="","",ROW()-9) | J24: FALSE | T24: =IF(U24="","",ROW()-6)
C25: FALSE | F25: =IF(G25="","",ROW()-9) | J25: FALSE | T25: =IF(U25="","",ROW()-6)
C26: FALSE | F26: =IF(G26="","",ROW()-9) | J26: FALSE | T26: =IF(U26="","",ROW()-6)
C27: FALSE | F27: =IF(G27="","",ROW()-9) | J27: FALSE | T27: =IF(U27="","",ROW()-6)
C28: FALSE | F28: =IF(G28="","",ROW()-9) | J28: FALSE | T28: =IF(U28="","",ROW()-6)
C29: FALSE | F29: =IF(G29="","",ROW()-9) | J29: FALSE | T29: =IF(U29="","",ROW()-6)
C30: FALSE | F30: =IF(G30="","",ROW()-9) | J30: FALSE | T30: =IF(U30="","",ROW()-6)
F31: =IF(G31="","",ROW()-9) | J31: FALSE | T31: =IF(U31="","",ROW()-6)
F32: =IF(G32="","",ROW()-9) | J32: FALSE | T32: =IF(U32="","",ROW()-6)
F33: =IF(G33="","",ROW()-9) | J33: FALSE | T33: =IF(U33="","",ROW()-6)
F34: =IF(G34="","",ROW()-9) | J34: FALSE | T34: =IF(U34="","",ROW()-6)
F35: =IF(G35="","",ROW()-9) | J35: FALSE | T35: =IF(U35="","",ROW()-6)
F36: =IF(G36="","",ROW()-9) | J36: FALSE | T36: =IF(U36="","",ROW()-6)
F37: =IF(G37="","",ROW()-9) | J37: FALSE | T37: =IF(U37="","",ROW()-6)
F38: =IF(G38="","",ROW()-9) | J38: FALSE | T38: =IF(U38="","",ROW()-6)
